<?xml version="1.0"?>
<robot name="rover_description" xmlns:xacro="http:/wiki:ros.org/xacro">
  <xacro:macro name="arm" params="parent">
  <joint name="arm_base_link_joint" type="fixed">
    <origin rpy="0.00000 0.00000 0.00000" xyz="0.00000 -0.75000 0.15000"/>
    <parent link="${parent}"/>
    <child link="arm_base_link"/>
  </joint>

  <joint name="central_link3_link_joint" type="fixed">
    <origin rpy="0.00000 0.00000 0.00000" xyz="0.00000 -0.30000 0.00000"/>
    <parent link="linkage_link3_link"/>
    <child link="central_link3_link"/>
  </joint>
  <joint name="joint_1_arm" type="continuous">
    <limit lower="0" upper="0" effort="0.00000" velocity="0.00000"/>
    <origin rpy="0.00000 0.00000 0.00000" xyz="0.00000 0.00000 0.55000"/>
    <parent link="link1_arm_link"/>
    <child link="link2_arm.001_link"/>
    <axis xyz="0.00000 0.00000 1.00000"/>
  </joint>
  <joint name="joint_arm_2" type="continuous">
    <limit lower="0" upper="0" effort="0.00000" velocity="0.00000"/>
    <origin rpy="0.00000 0.00000 0.00000" xyz="0.00000 0.00000 0.10000"/>
    <parent link="linkage_arm2_arm3_link"/>
    <child link="linkage_link3_link"/>
    <axis xyz="0.00000 0.00000 1.00000"/>
  </joint>
  <joint name="joint_linkage_2_link2" type="fixed">
    <origin rpy="0.00000 0.00000 0.00000" xyz="0.00000 -0.55000 0.10000"/>
    <parent link="link2_arm.001_link"/>
    <child link="linkage_arm2_arm3_link"/>
  </joint>
  <joint name="joint_arm_4_prismatic" type="prismatic">
    <limit lower="-3.14000" upper="3.14000" effort="0.00000" velocity="0.00000"/>
    <origin rpy="0.00000 0.00000 0.00000" xyz="0.00000 0.00000 -0.60000"/>
    <parent link="link3_final_link"/>
    <child link="link3_arm_link"/>
    <axis xyz="0.00000 0.00000 1.00000"/>
  </joint>

   <joint name="joint_gripper_left" type="prismatic">
    <limit lower="-3.14000" upper="3.14000" effort="0.00000" velocity="0.00000"/>
    <origin rpy="0.00000 1.57080 0.00000" xyz="-0.47000 0.00000 0.25000"/>
    <parent link="gripper_base_link"/>
    <child link="left_gripper_link"/>
    <axis xyz="0.00000 0.00000 1.00000"/>
  </joint>
  <joint name="joint_gripper_right" type="prismatic">
    <limit lower="-3.14000" upper="3.14000" effort="0.00000" velocity="0.00000"/>
    <origin rpy="0.00000 -1.57080 0.00000" xyz="0.47000 0.00000 0.25000"/>
    <parent link="gripper_base_link"/>
    <child link="right_gripper_link"/>
    <axis xyz="0.00000 0.00000 1.00000"/>
  </joint>
  <joint name="joint_gripper_rotacion" type="continuous">
    <limit lower="0" upper="0" effort="0.00000" velocity="0.00000"/>
    <origin rpy="3.14159 -0.00000 3.14159" xyz="0.00000 -0.00000 -0.90000"/>
    <parent link="link3_arm_link"/>
    <child link="gripper_base_link"/>
    <axis xyz="0.00000 0.00000 1.00000"/>
  </joint>
  <joint name="joint_link_1_2_base_arm" type="fixed">
    <origin rpy="0.00000 0.00000 0.00000" xyz="0.00000 0.00000 0.70000"/>
    <parent link="arm_base_link"/>
    <child link="link1_arm_link"/>
  </joint>


  <joint name="link3_final_link_joint" type="fixed">
    <origin rpy="0.00000 0.00000 0.00000" xyz="0.00000 -0.30000 -0.00000"/>
    <parent link="central_link3_link"/>
    <child link="link3_final_link"/>
  </joint>
  <link name="arm_base_link">
    <collision name="arm_base_collision">
      <origin rpy="0.00000 0.00000 0.00000" xyz="0.00000 -0.00000 0.00000"/>
      <geometry>
        <cylinder radius="0.25000" length="0.10000"/>
      </geometry>
    </collision>
    <inertial>
      <inertia ixx="0.02469" ixy="0.00000" ixz="0.00000" iyy="0.02469" iyz="0.00000" izz="0.04688"/>
      <origin rpy="0.00000 0.00000 0.00000" xyz="0.00000 -0.00000 0.00000"/>
      <mass value="1.50000"/>
    </inertial>
    <visual name="arm_base">
      <origin rpy="0.00000 0.00000 0.00000" xyz="0.00000 0.00000 0.00000"/>
      <geometry>
        <cylinder radius="0.25000" length="0.10000"/>
      </geometry>
    </visual>
  </link>

  <link name="central_link3_link">
    <collision name="central_link3_collision">
      <origin rpy="0.00000 0.00000 0.00000" xyz="0.00000 -0.00000 -0.00000"/>
      <geometry>
        <box size="0.20000 0.20000 0.10000"/>
      </geometry>
    </collision>
    <inertial>
      <inertia ixx="0.00425" ixy="0.00000" ixz="0.00000" iyy="0.00331" iyz="0.00000" izz="0.00706"/>
      <origin rpy="0.00000 0.00000 0.00000" xyz="0.00000 -0.00000 -0.00000"/>
      <mass value="0.30000"/>
    </inertial>
    <visual name="central_link3">
      <origin rpy="0.00000 0.00000 0.00000" xyz="0.00000 0.00000 -0.00000"/>
      <geometry>
        <box size="0.35000 0.40000 0.10000"/>
      </geometry>
    </visual>
  </link>

  <link name="gripper_base_link">
    <collision name="gripper_base_collision">
      <origin rpy="3.14159 0.00000 3.14159" xyz="-0.00000 0.00000 0.00000"/>
      <geometry>
        <box size="1.00000 0.40000 0.10000"/>
      </geometry>
    </collision>
    <inertial>
      <inertia ixx="0.00425" ixy="0.00000" ixz="-0.00000" iyy="0.02525" iyz="0.00000" izz="0.02900"/>
      <origin rpy="0.00000 0.00000 0.00000" xyz="-0.00000 0.00000 0.00000"/>
      <mass value="0.30000"/>
    </inertial>
    <visual name="gripper_base">
      <origin rpy="3.14159 0.00000 3.14159" xyz="-0.00000 0.00000 0.00000"/>
      <geometry>
        <box size="1.00000 0.40000 0.10000"/>
      </geometry>
    </visual>
  </link>
  <link name="left_gripper_link">
    <collision name="left_gripper_collision">
      <origin rpy="-0.00000 1.57080 0.00000" xyz="-0.00000 0.00000 0.00000"/>
      <geometry>
        <box size="0.05000 0.40000 0.40000"/>
      </geometry>
    </collision>
    <inertial>
      <inertia ixx="0.00800" ixy="0.00000" ixz="0.00000" iyy="0.00406" iyz="0.00000" izz="0.00406"/>
      <origin rpy="0.00000 0.00000 0.00000" xyz="-0.00000 0.00000 0.00000"/>
      <mass value="0.30000"/>
    </inertial>
    <visual name="left_gripper">
      <origin rpy="-0.00000 1.57080 0.00000" xyz="-0.00000 0.00000 0.00000"/>
      <geometry>
        <box size="0.05000 0.40000 0.40000"/>
      </geometry>
    </visual>
  </link>


  <link name="link1_arm_link">
    <collision name="link1_arm_collision">
      <origin rpy="0.00000 0.00000 0.00000" xyz="0.00000 -0.00000 -0.10000"/>
      <geometry>
        <cylinder radius="0.15000" length="1.15000"/>
      </geometry>
    </collision>
    <inertial>
      <inertia ixx="0.17375" ixy="0.00000" ixz="0.00000" iyy="0.17375" iyz="0.00000" izz="0.01688"/>
      <origin rpy="0.00000 0.00000 0.00000" xyz="0.00000 -0.00000 -0.10000"/>
      <mass value="1.50000"/>
    </inertial>
    <visual name="link1_arm">
      <origin rpy="0.00000 0.00000 0.00000" xyz="0.00000 0.00000 -0.10000"/>
      <geometry>
        <cylinder radius="0.15000" length="1.15000"/>
      </geometry>
    </visual>
  </link>
  <link name="link2_arm.001_link">
    <collision name="link2_arm.001_collision">
      <origin rpy="0.00000 0.00000 0.00000" xyz="0.00000 -0.25000 0.00000"/>
      <geometry>
        <cylinder radius="0.25000" length="0.15000"/>
      </geometry>
    </collision>
    <inertial>
      <inertia ixx="0.00525" ixy="0.00000" ixz="0.00000" iyy="0.00525" iyz="0.00000" izz="0.00938"/>
      <origin rpy="0.00000 0.00000 0.00000" xyz="0.00000 -0.25000 0.00000"/>
      <mass value="0.30000"/>
    </inertial>
    <visual name="link2_arm.001">
      <origin rpy="0.00000 0.00000 0.00000" xyz="0.00000 -0.25000 0.00000"/>
      <geometry>
        <cylinder radius="0.25000" length="0.15000"/>
      </geometry>
    </visual>
  </link>
  <link name="link3_arm_link">
    <collision name="link3_arm_collision">
      <origin rpy="0.00000 0.00000 0.00000" xyz="0.00000 0.00000 -0.00000"/>
      <geometry>
        <cylinder radius="0.10000" length="1.80000"/>
      </geometry>
    </collision>
    <inertial>
      <inertia ixx="0.21800" ixy="0.00000" ixz="0.00000" iyy="0.21800" iyz="0.00000" izz="0.00400"/>
      <origin rpy="0.00000 0.00000 0.00000" xyz="0.00000 0.00000 0.00000"/>
      <mass value="0.80000"/>
    </inertial>
    <visual name="link3_arm">
      <origin rpy="0.00000 0.00000 0.00000" xyz="0.00000 0.00000 -0.00000"/>
      <geometry>
        <cylinder radius="0.10000" length="1.80000"/>
      </geometry>
    </visual>
  </link>
  <link name="link3_final_link">
    <collision name="link3_final_collision">
      <origin rpy="0.00000 0.00000 0.00000" xyz="0.00000 0.00000 0.00000"/>
      <geometry>
        <mesh filename="file://$(find rover_description)/meshes/dae/Torus.005.dae" scale="0.16000 0.16000 0.20000"/>
      </geometry>
    </collision>
    <inertial>
      <inertia ixx="0.00296" ixy="0.00000" ixz="-0.00000" iyy="0.00296" iyz="0.00000" izz="0.00563"/>
      <origin rpy="0.00000 0.00000 0.00000" xyz="0.00000 -0.00000 0.00000"/>
      <mass value="0.30000"/>
    </inertial>
    <visual name="link3_final">
      <origin rpy="0.00000 0.00000 0.00000" xyz="0.00000 -0.00000 0.00000"/>
      <geometry>
        <mesh filename="file://$(find rover_description)/meshes/dae/Torus.005.dae" scale="0.16000 0.16000 0.20000"/>
      </geometry>
    </visual>
  </link>
  <link name="linkage_arm2_arm3_link">
    <collision name="linkage_arm2_arm3_collision">
      <origin rpy="0.00000 0.00000 0.00000" xyz="0.00000 -0.00000 0.00000"/>
      <geometry>
        <cylinder radius="0.15000" length="0.06000"/>
      </geometry>
    </collision>
    <inertial>
      <inertia ixx="0.00178" ixy="0.00000" ixz="0.00000" iyy="0.00178" iyz="0.00000" izz="0.00338"/>
      <origin rpy="0.00000 0.00000 0.00000" xyz="0.00000 -0.00000 0.00000"/>
      <mass value="0.30000"/>
    </inertial>
    <visual name="linkage_arm2_arm3">
      <origin rpy="0.00000 0.00000 0.00000" xyz="0.00000 -0.00000 0.00000"/>
      <geometry>
        <cylinder radius="0.15000" length="0.06000"/>
      </geometry>
    </visual>
  </link>
  <link name="linkage_link3_link">
    <collision name="linkage_link3_collision">
      <origin rpy="0.00000 0.00000 0.00000" xyz="0.00000 0.00000 0.00000"/>
      <geometry>
        <mesh filename="file://$(find rover_description)/meshes/dae/Torus.004.dae" scale="0.16000 0.16000 0.20000"/>
      </geometry>
    </collision>
    <inertial>
      <inertia ixx="0.00296" ixy="0.00000" ixz="-0.00000" iyy="0.00296" iyz="0.00000" izz="0.00563"/>
      <origin rpy="0.00000 0.00000 0.00000" xyz="0.00000 0.00000 0.00000"/>
      <mass value="0.30000"/>
    </inertial>
    <visual name="linkage_link3">
      <origin rpy="0.00000 0.00000 0.00000" xyz="0.00000 0.00000 0.00000"/>
      <geometry>
        <mesh filename="file://$(find rover_description)/meshes/dae/Torus.004.dae" scale="0.16000 0.16000 0.20000"/>
      </geometry>
    </visual>
  </link>
  <link name="right_gripper_link">
    <collision name="right_gripper_collision">
      <origin rpy="0.00000 -1.57080 0.00000" xyz="0.00000 0.00000 0.00000"/>
      <geometry>
        <box size="0.05000 0.40000 0.40000"/>
      </geometry>
    </collision>
    <inertial>
      <inertia ixx="0.00800" ixy="0.00000" ixz="-0.00000" iyy="0.00406" iyz="0.00000" izz="0.00406"/>
      <origin rpy="0.00000 0.00000 0.00000" xyz="0.00000 0.00000 0.00000"/>
      <mass value="0.30000"/>
    </inertial>
    <visual name="right_gripper">
      <origin rpy="0.00000 -1.57080 0.00000" xyz="0.00000 0.00000 0.00000"/>
      <geometry>
        <box size="0.05000 0.40000 0.40000"/>
      </geometry>
    </visual>
  </link>


  </xacro:macro>
</robot>
