<?xml version="1.0"?>
<robot name="rover_description" xmlns:xacro="http:/wiki:ros.org/xacro">  
  <xacro:macro name="wheels" params="parent">
  <joint name="back_linkage_axis_left_link_joint" type="fixed">
    <origin rpy="0.00000 -1.57080 0.00000" xyz="0.70000 0.00000 -0.13000"/>
    <parent link="back_axis_link"/>
    <child link="back_linkage_axis_left_link"/>
  </joint>
  <joint name="back_linkage_axis_right_link_joint" type="fixed">
    <origin rpy="-0.00000 1.57080 0.00000" xyz="-0.70000 0.00000 -0.13000"/>
    <parent link="back_axis_link"/>
    <child link="back_linkage_axis_right_link"/>
  </joint>

  <joint name="joint_back_right_2_linkage_axis" type="fixed">
    <origin rpy="0.00000 -1.57080 0.00000" xyz="0.17000 0.00000 -0.08000"/>
    <parent link="back_linkage_axis_right_link"/>
    <child link="back_right_axis_link"/>
  </joint>

  <joint name="joint_central_2_back_axis" type="fixed">
    <origin rpy="0.00000 0.00000 0.00000" xyz="0.00000 1.00000 -0.05000"/>
    <parent link="central_axis_link"/>
    <child link="back_axis_link"/>
  </joint>
  <joint name="joint_central_2_front_axis" type="fixed">
    <origin rpy="0.00000 0.00000 0.00000" xyz="0.00000 -1.00000 -0.05000"/>
    <parent link="central_axis_link"/>
    <child link="front_axis_link"/>
  </joint>
  <joint name="joint_centralaxis_2_base" type="fixed">
    <origin rpy="0.00000 0.00000 0.00000" xyz="0.00000 0.00000 -0.15000"/>
    <parent link="${parent}"/>
    <child link="central_axis_link"/>
  </joint>
  <joint name="joint_front_right_axis_2_linkage" type="fixed">
    <origin rpy="0.00000 -1.57080 0.00000" xyz="0.17000 0.00000 -0.08000"/>
    <parent link="front_linkage_axis_right_link"/>
    <child link="front_right_axis_link"/>
  </joint>

  <joint name="joint_left_2_linkage_axis" type="fixed">
    <origin rpy="-0.00000 1.57080 0.00000" xyz="-0.17000 0.00000 -0.08000"/>
    <parent link="back_linkage_axis_left_link"/>
    <child link="back_left_axis_link"/>
  </joint>
  <joint name="joint_left_axis_2_linkage_front" type="fixed">
    <origin rpy="-0.00000 1.57080 0.00000" xyz="-0.17000 0.00000 -0.08000"/>
    <parent link="front_linkage_axis_left_link"/>
    <child link="front_left_axis_link"/>
  </joint>

  <joint name="joint_linkage_2_front__right_axis" type="fixed">
    <origin rpy="-0.00000 1.57080 0.00000" xyz="-0.70000 0.00000 -0.13000"/>
    <parent link="front_axis_link"/>
    <child link="front_linkage_axis_right_link"/>
  </joint>
  <joint name="joint_linkage_2_front_axis_left" type="fixed">
    <origin rpy="0.00000 -1.57080 0.00000" xyz="0.70000 0.00000 -0.13000"/>
    <parent link="front_axis_link"/>
    <child link="front_linkage_axis_left_link"/>
  </joint>

  <joint name="joint_wheel_2_rim_back_left" type="fixed">
    <origin rpy="3.14159 1.57080 3.14159" xyz="-0.00000 0.00000 0.00000"/>
    <parent link="rim_back_left_link"/>
    <child link="wheel_back_left_link"/>
  </joint>
  <joint name="joint_wheel_2_rim_back_right" type="fixed">
    <origin rpy="0.00000 -1.57080 0.00000" xyz="0.00000 0.00000 0.00000"/>
    <parent link="rim_back_right_link"/>
    <child link="wheel_back_right_link"/>
  </joint>
  <joint name="joint_wheel_2_rim_fornt_left" type="fixed">
    <origin rpy="3.14159 1.57080 3.14159" xyz="0.00000 0.00000 -0.00000"/>
    <parent link="rim_front_left_link"/>
    <child link="wheel_front_left_link"/>
  </joint>
  <joint name="joint_wheel_2_rim_front_right" type="fixed">
    <origin rpy="0.00000 -1.57080 0.00000" xyz="0.00000 0.00000 0.00000"/>
    <parent link="rim_front_right_link"/>
    <child link="wheel_front_right_link"/>
  </joint>
  <joint name="joint_wheel_back_left" type="continuous">
    <limit lower="0" upper="0" effort="0.00000" velocity="0.00000"/>
    <origin rpy="-0.00000 1.57080 0.00000" xyz="0.07000 0.00000 -0.00000"/>
    <parent link="back_left_axis_link"/>
    <child link="rim_back_left_link"/>
    <axis xyz="0.00000 0.00000 1.00000"/>
  </joint>
  <joint name="joint_wheel_banck_right" type="continuous">
    <limit lower="0" upper="0" effort="0.00000" velocity="0.00000"/>
    <origin rpy="0.00000 -1.57080 0.00000" xyz="-0.07000 0.00000 -0.00000"/>
    <parent link="back_right_axis_link"/>
    <child link="rim_back_right_link"/>
    <axis xyz="0.00000 0.00000 1.00000"/>
  </joint>
  <joint name="joint_wheel_front_left" type="continuous">
    <limit lower="0" upper="0" effort="0.00000" velocity="0.00000"/>
    <origin rpy="-0.00000 1.57080 0.00000" xyz="0.07000 0.00000 0.00000"/>
    <parent link="front_left_axis_link"/>
    <child link="rim_front_left_link"/>
    <axis xyz="0.00000 0.00000 1.00000"/>
  </joint>
  <joint name="joint_wheel_front_right" type="continuous">
    <limit lower="0" upper="0" effort="0.00000" velocity="0.00000"/>
    <origin rpy="0.00000 -1.57080 0.00000" xyz="-0.07000 0.00000 -0.00000"/>
    <parent link="front_right_axis_link"/>
    <child link="rim_front_right_link"/>
    <axis xyz="0.00000 0.00000 1.00000"/>
  </joint>

  <link name="back_axis_link">
    <collision name="back_axis_collision">
      <origin rpy="0.00000 0.00000 0.00000" xyz="0.00000 0.00000 0.00000"/>
      <geometry>
        <box size="1.50000 0.05000 0.05000"/>
      </geometry>
    </collision>
    <inertial>
      <inertia ixx="0.00033" ixy="0.00000" ixz="0.00000" iyy="0.15017" iyz="0.00000" izz="0.15017"/>
      <origin rpy="0.00000 0.00000 0.00000" xyz="0.00000 0.00000 0.00000"/>
      <mass value="0.80000"/>
    </inertial>
    <visual name="back_axis">
      <origin rpy="0.00000 0.00000 0.00000" xyz="0.00000 0.00000 0.00000"/>
      <geometry>
        <box size="1.50000 0.05000 0.05000"/>
      </geometry>
    </visual>
  </link>
  <link name="back_left_axis_link">
    <collision name="back_left_axis_collision">
      <origin rpy="0.00000 0.00000 0.00000" xyz="0.00000 0.00000 -0.00000"/>
      <geometry>
        <box size="0.20000 0.05000 0.05000"/>
      </geometry>
    </collision>
    <inertial>
      <inertia ixx="0.00021" ixy="0.00000" ixz="0.00000" iyy="0.00177" iyz="0.00000" izz="0.00177"/>
      <origin rpy="0.00000 0.00000 0.00000" xyz="0.00000 0.00000 -0.00000"/>
      <mass value="0.50000"/>
    </inertial>
    <visual name="back_left_axis">
      <origin rpy="0.00000 0.00000 0.00000" xyz="0.00000 0.00000 -0.00000"/>
      <geometry>
        <box size="0.20000 0.05000 0.05000"/>
      </geometry>
    </visual>
  </link>
  <link name="back_linkage_axis_left_link">
    <collision name="back_linkage_axis_left_collision">
      <origin rpy="-0.00000 1.57080 0.00000" xyz="0.00000 0.00000 -0.00000"/>
      <geometry>
        <box size="0.05000 0.05000 0.30000"/>
      </geometry>
    </collision>
    <inertial>
      <inertia ixx="0.00385" ixy="0.00000" ixz="0.00000" iyy="0.00385" iyz="0.00000" izz="0.00021"/>
      <origin rpy="0.00000 0.00000 0.00000" xyz="0.00000 0.00000 -0.00000"/>
      <mass value="0.50000"/>
    </inertial>
    <visual name="back_linkage_axis_left">
      <origin rpy="-0.00000 1.57080 0.00000" xyz="0.00000 0.00000 0.00000"/>
      <geometry>
        <box size="0.05000 0.05000 0.30000"/>
      </geometry>
    </visual>
  </link>
  <link name="back_linkage_axis_right_link">
    <collision name="back_linkage_axis_right_collision">
      <origin rpy="0.00000 -1.57080 0.00000" xyz="-0.00000 0.00000 -0.00000"/>
      <geometry>
        <box size="0.05000 0.05000 0.30000"/>
      </geometry>
    </collision>
    <inertial>
      <inertia ixx="0.00385" ixy="0.00000" ixz="-0.00000" iyy="0.00385" iyz="0.00000" izz="0.00021"/>
      <origin rpy="0.00000 0.00000 0.00000" xyz="-0.00000 0.00000 -0.00000"/>
      <mass value="0.50000"/>
    </inertial>
    <visual name="back_linkage_axis_right">
      <origin rpy="0.00000 -1.57080 0.00000" xyz="0.00000 0.00000 0.00000"/>
      <geometry>
        <box size="0.05000 0.05000 0.30000"/>
      </geometry>
    </visual>
  </link>
  <link name="back_right_axis_link">
    <collision name="back_right_axis_collision">
      <origin rpy="0.00000 0.00000 0.00000" xyz="-0.00000 0.00000 -0.00000"/>
      <geometry>
        <box size="0.20000 0.05000 0.05000"/>
      </geometry>
    </collision>
    <inertial>
      <inertia ixx="0.00021" ixy="0.00000" ixz="0.00000" iyy="0.00177" iyz="0.00000" izz="0.00177"/>
      <origin rpy="0.00000 0.00000 0.00000" xyz="-0.00000 0.00000 -0.00000"/>
      <mass value="0.50000"/>
    </inertial>
    <visual name="back_right_axis">
      <origin rpy="0.00000 0.00000 0.00000" xyz="0.00000 0.00000 -0.00000"/>
      <geometry>
        <box size="0.20000 0.05000 0.05000"/>
      </geometry>
    </visual>
  </link>
  <link name="central_axis_link">
    <collision name="central_axis_collision">
      <origin rpy="0.00000 0.00000 0.00000" xyz="0.00000 0.00000 0.00000"/>
      <geometry>
        <box size="0.10000 2.05000 0.10000"/>
      </geometry>
    </collision>
    <inertial>
      <inertia ixx="0.35104" ixy="0.00000" ixz="0.00000" iyy="0.00167" iyz="0.00000" izz="0.35104"/>
      <origin rpy="0.00000 0.00000 0.00000" xyz="0.00000 0.00000 0.00000"/>
      <mass value="1.00000"/>
    </inertial>
    <visual name="central_axis">
      <origin rpy="0.00000 0.00000 0.00000" xyz="0.00000 0.00000 0.00000"/>
      <geometry>
        <box size="0.10000 2.05000 0.10000"/>
      </geometry>
    </visual>
  </link>

  <link name="front_axis_link">
    <collision name="front_axis_collision">
      <origin rpy="0.00000 0.00000 0.00000" xyz="0.00000 0.00000 0.00000"/>
      <geometry>
        <box size="1.50000 0.05000 0.05000"/>
      </geometry>
    </collision>
    <inertial>
      <inertia ixx="0.00033" ixy="0.00000" ixz="0.00000" iyy="0.15017" iyz="0.00000" izz="0.15017"/>
      <origin rpy="0.00000 0.00000 0.00000" xyz="0.00000 0.00000 0.00000"/>
      <mass value="0.80000"/>
    </inertial>
    <visual name="front_axis">
      <origin rpy="0.00000 0.00000 0.00000" xyz="0.00000 0.00000 0.00000"/>
      <geometry>
        <box size="1.50000 0.05000 0.05000"/>
      </geometry>
    </visual>
  </link>
  <link name="front_left_axis_link">
    <collision name="front_left_axis_collision">
      <origin rpy="0.00000 0.00000 0.00000" xyz="0.00000 0.00000 0.00000"/>
      <geometry>
        <box size="0.20000 0.05000 0.05000"/>
      </geometry>
    </collision>
    <inertial>
      <inertia ixx="0.00021" ixy="0.00000" ixz="0.00000" iyy="0.00177" iyz="0.00000" izz="0.00177"/>
      <origin rpy="0.00000 0.00000 0.00000" xyz="-0.00000 0.00000 0.00000"/>
      <mass value="0.50000"/>
    </inertial>
    <visual name="front_left_axis">
      <origin rpy="0.00000 0.00000 0.00000" xyz="0.00000 0.00000 0.00000"/>
      <geometry>
        <box size="0.20000 0.05000 0.05000"/>
      </geometry>
    </visual>
  </link>
  <link name="front_linkage_axis_left_link">
    <collision name="front_linkage_axis_left_collision">
      <origin rpy="-0.00000 1.57080 0.00000" xyz="-0.00000 0.00000 0.00000"/>
      <geometry>
        <box size="0.05000 0.05000 0.30000"/>
      </geometry>
    </collision>
    <inertial>
      <inertia ixx="0.00385" ixy="0.00000" ixz="0.00000" iyy="0.00385" iyz="0.00000" izz="0.00021"/>
      <origin rpy="0.00000 0.00000 0.00000" xyz="-0.00000 0.00000 0.00000"/>
      <mass value="0.50000"/>
    </inertial>
    <visual name="front_linkage_axis_left">
      <origin rpy="-0.00000 1.57080 0.00000" xyz="-0.00000 0.00000 0.00000"/>
      <geometry>
        <box size="0.05000 0.05000 0.30000"/>
      </geometry>
    </visual>
  </link>
  <link name="front_linkage_axis_right_link">
    <collision name="front_linkage_axis_right_collision">
      <origin rpy="0.00000 -1.57080 0.00000" xyz="-0.00000 0.00000 -0.00000"/>
      <geometry>
        <box size="0.05000 0.05000 0.30000"/>
      </geometry>
    </collision>
    <inertial>
      <inertia ixx="0.00385" ixy="0.00000" ixz="-0.00000" iyy="0.00385" iyz="0.00000" izz="0.00021"/>
      <origin rpy="0.00000 0.00000 0.00000" xyz="-0.00000 0.00000 -0.00000"/>
      <mass value="0.50000"/>
    </inertial>
    <visual name="front_linkage_axis_right">
      <origin rpy="0.00000 -1.57080 0.00000" xyz="0.00000 0.00000 0.00000"/>
      <geometry>
        <box size="0.05000 0.05000 0.30000"/>
      </geometry>
    </visual>
  </link>
  <link name="front_right_axis_link">
    <collision name="front_right_axis_collision">
      <origin rpy="0.00000 0.00000 0.00000" xyz="-0.00000 0.00000 -0.00000"/>
      <geometry>
        <box size="0.20000 0.05000 0.05000"/>
      </geometry>
    </collision>
    <inertial>
      <inertia ixx="0.00021" ixy="0.00000" ixz="0.00000" iyy="0.00177" iyz="0.00000" izz="0.00177"/>
      <origin rpy="0.00000 0.00000 0.00000" xyz="-0.00000 0.00000 -0.00000"/>
      <mass value="0.50000"/>
    </inertial>
    <visual name="front_right_axis">
      <origin rpy="0.00000 0.00000 0.00000" xyz="0.00000 0.00000 -0.00000"/>
      <geometry>
        <box size="0.20000 0.05000 0.05000"/>
      </geometry>
    </visual>
  </link>

  <link name="rim_back_left_link">
    <collision name="rim_back_left_collision">
      <origin rpy="0.00000 0.00000 0.00000" xyz="0.00000 0.00000 0.00000"/>
      <geometry>
        <cylinder radius="0.12500" length="0.05000"/>
      </geometry>
    </collision>
    <inertial>
      <inertia ixx="0.00781" ixy="0.00000" ixz="-0.00000" iyy="0.00411" iyz="0.00000" izz="0.00411"/>
      <origin rpy="0.00000 0.00000 0.00000" xyz="0.00000 0.00000 0.00000"/>
      <mass value="1.00000"/>
    </inertial>
    <visual name="rim_back_left">
      <origin rpy="0.00000 0.00000 0.00000" xyz="-0.00000 0.00000 0.00000"/>
      <geometry>
        <cylinder radius="0.12500" length="0.05000"/>
      </geometry>
    </visual>
  </link>
  <link name="rim_back_right_link">
    <collision name="rim_back_right_collision">
      <origin rpy="3.14159 -0.00000 3.14159" xyz="0.00000 0.00000 0.00000"/>
      <geometry>
        <cylinder radius="0.12500" length="0.05000"/>
      </geometry>
    </collision>
    <inertial>
      <inertia ixx="0.01125" ixy="0.00000" ixz="0.00000" iyy="0.00583" iyz="0.00000" izz="0.00583"/>
      <origin rpy="0.00000 0.00000 0.00000" xyz="0.00000 0.00000 0.00000"/>
      <mass value="1.00000"/>
    </inertial>
    <visual name="rim_back_right">
      <origin rpy="3.14159 0.00000 3.14159" xyz="0.00000 0.00000 0.00000"/>
      <geometry>
        <cylinder radius="0.15000" length="0.05000"/>
      </geometry>
    </visual>
  </link>
  <link name="rim_front_left_link">
    <collision name="rim_front_left_collision">
      <origin rpy="0.00000 0.00000 0.00000" xyz="0.00000 0.00000 -0.00000"/>
      <geometry>
        <cylinder radius="0.12500" length="0.05000"/>
      </geometry>
    </collision>
    <inertial>
      <inertia ixx="0.00781" ixy="0.00000" ixz="-0.00000" iyy="0.00411" iyz="0.00000" izz="0.00411"/>
      <origin rpy="0.00000 0.00000 0.00000" xyz="0.00000 0.00000 0.00000"/>
      <mass value="1.00000"/>
    </inertial>
    <visual name="rim_front_left">
      <origin rpy="0.00000 0.00000 0.00000" xyz="0.00000 0.00000 -0.00000"/>
      <geometry>
        <cylinder radius="0.12500" length="0.05000"/>
      </geometry>
    </visual>
  </link>
  <link name="rim_front_right_link">
    <collision name="rim_front_right_collision">
      <origin rpy="3.14159 -0.00000 3.14159" xyz="0.00000 0.00000 0.00000"/>
      <geometry>
        <cylinder radius="0.12500" length="0.05000"/>
      </geometry>
    </collision>
    <inertial>
      <inertia ixx="0.00781" ixy="0.00000" ixz="0.00000" iyy="0.00411" iyz="0.00000" izz="0.00411"/>
      <origin rpy="0.00000 0.00000 0.00000" xyz="0.00000 0.00000 0.00000"/>
      <mass value="1.00000"/>
    </inertial>
    <visual name="rim_front_right">
      <origin rpy="3.14159 0.00000 3.14159" xyz="0.00000 0.00000 0.00000"/>
      <geometry>
        <cylinder radius="0.12500" length="0.05000"/>
      </geometry>
    </visual>
  </link>

  <link name="wheel_back_left_link">
    <collision name="wheel_back_left_collision">
      <origin rpy="0.00000 1.57080 -0.00000" xyz="0.00000 0.00000 0.00000"/>
      <geometry>
        <mesh filename="file://$(find rover_description)/meshes/dae/Torus.003.dae" scale="0.20000 0.20000 0.30000"/>
      </geometry>
    </collision>
    <inertial>
      <inertia ixx="0.02932" ixy="0.00000" ixz="0.00000" iyy="0.01577" iyz="-0.00000" izz="0.01577"/>
      <origin rpy="0.00000 0.00000 0.00000" xyz="0.00000 -0.00000 0.00000"/>
      <mass value="1.00000"/>
    </inertial>
    <visual name="wheel_back_left">
      <origin rpy="3.14159 -1.57080 3.14159" xyz="0.00000 0.00000 0.00000"/>
      <geometry>
        <mesh filename="file://$(find rover_description)/meshes/dae/Torus.003.dae" scale="0.20000 0.20000 0.30000"/>
      </geometry>
    </visual>
  </link>
  <link name="wheel_back_right_link">
    <collision name="wheel_back_right_collision">
      <origin rpy="0.00000 1.57080 -0.00000" xyz="-0.00000 0.00000 -0.00000"/>
      <geometry>
        <mesh filename="file://$(find rover_description)/meshes/dae/Torus.001.dae" scale="0.20000 0.20000 0.30000"/>
      </geometry>
    </collision>
    <inertial>
      <inertia ixx="0.02932" ixy="0.00000" ixz="0.00000" iyy="0.01577" iyz="-0.00000" izz="0.01577"/>
      <origin rpy="0.00000 0.00000 0.00000" xyz="-0.00000 -0.00000 0.00000"/>
      <mass value="1.00000"/>
    </inertial>
    <visual name="wheel_back_right">
      <origin rpy="3.14159 -1.57080 3.14159" xyz="-0.00000 0.00000 -0.00000"/>
      <geometry>
        <mesh filename="file://$(find rover_description)/meshes/dae/Torus.001.dae" scale="0.20000 0.20000 0.30000"/>
      </geometry>
    </visual>
  </link>
  <link name="wheel_front_left_link">
    <collision name="wheel_front_left_collision">
      <origin rpy="0.00000 1.57080 -0.00000" xyz="-0.00000 0.00000 -0.00000"/>
      <geometry>
        <mesh filename="file://$(find rover_description)/meshes/dae/Torus.002.dae" scale="0.20000 0.20000 0.30000"/>
      </geometry>
    </collision>
    <inertial>
      <inertia ixx="0.02932" ixy="0.00000" ixz="0.00000" iyy="0.01577" iyz="-0.00000" izz="0.01577"/>
      <origin rpy="0.00000 0.00000 0.00000" xyz="-0.00000 0.00000 -0.00000"/>
      <mass value="1.00000"/>
    </inertial>
    <visual name="wheel_front_left">
      <origin rpy="3.14159 -1.57080 3.14159" xyz="-0.00000 0.00000 -0.00000"/>
      <geometry>
        <mesh filename="file://$(find rover_description)/meshes/dae/Torus.002.dae" scale="0.20000 0.20000 0.30000"/>
      </geometry>
    </visual>
  </link>
  <link name="wheel_front_right_link">
    <collision name="wheel_front_right_collision">
      <origin rpy="0.00000 1.57080 -0.00000" xyz="-0.00000 0.00000 -0.00000"/>
      <geometry>
        <mesh filename="file://$(find rover_description)/meshes/dae/Torus.dae" scale="0.20000 0.20000 0.30000"/>
      </geometry>
    </collision>
    <inertial>
      <inertia ixx="0.02932" ixy="0.00000" ixz="0.00000" iyy="0.01577" iyz="-0.00000" izz="0.01577"/>
      <origin rpy="0.00000 0.00000 0.00000" xyz="-0.00000 0.00000 0.00000"/>
      <mass value="1.00000"/>
    </inertial>
    <visual name="wheel_front_right">
      <origin rpy="3.14159 -1.57080 3.14159" xyz="-0.00000 0.00000 -0.00000"/>
      <geometry>
        <mesh filename="file://$(find rover_description)/meshes/dae/Torus.dae" scale="0.20000 0.20000 0.30000"/>
      </geometry>
    </visual>
  </link>
  </xacro:macro>

</robot>
